Workbook
Name Sheet_1_ListCol_1: [1]INTER!$A$8:$A$45

Sheet Input
A1: Goods and Services Tax - GSTR-2B
A4: Taxable inward supplies received from registered persons
A5: GSTIN of supplier | B5: Trade/Legal name | C5: Invoice Details | G5: Place of supply | H5: Supply Attract Reverse Charge | I5: Taxable Value (₹) | J5: Tax Amount | N5: GSTR-1/1A/IFF/GSTR-5 Period | O5: GSTR-1/1A/IFF/GSTR-5 Filing Date | P5: ITC Availability | Q5: Reason | R5: Applicable % of Tax Rate | S5: Source | T5: IRN | U5: IRN Date
C6: Invoice number | D6: Invoice type | E6: Invoice Date | F6: Invoice Value(₹) | J6: Integrated Tax(₹) | K6: Central Tax(₹) | L6: State/UT Tax(₹) | M6: Cess(₹)
A7: 29AAICA3918J1ZE | B7: AMAZON SELLER SERVICES PVT LTD | C7: KA-2627-1841559 | D7: Regular | E7: 31/08/2026 | F7: 1864.4 | G7: Tamil Nadu | H7: No | I7: 1580 | J7: 284.4 | K7: 0 | L7: 0 | M7: 0 | N7: Aug'26 | O7: 11/09/2026 | P7: Yes | R7: 100%
A8: 29AAICA3918J1ZE | B8: AMAZON SELLER SERVICES PVT LTD | C8: KA-2627-1842315 | D8: Regular | E8: 31/08/2026 | F8: 2328.14 | G8: Tamil Nadu | H8: No | I8: 1973 | J8: 355.14 | K8: 0 | L8: 0 | M8: 0 | N8: Aug'26 | O8: 11/09/2026 | P8: Yes | R8: 100%
A9: 33AAJCC8517E1ZS | B9: COCOBLU RETAIL LIMITED | C9: MAA4-2791806 | D9: Regular | E9: 15/08/2026 | F9: 2186.82 | G9: Tamil Nadu | H9: No | I9: 2082.68 | J9: 0 | K9: 52.07 | L9: 52.07 | M9: 0 | N9: Aug'26 | O9: 11/09/2026 | P9: Yes | R9: 100%
A10: 29AACCF0683K1ZD | B10: FLIPKART INTERNET PRIVATE LIMITED | C10: FKRKA27000994321 | D10: Regular | E10: 31/08/2026 | F10: 1231.48 | G10: Tamil Nadu | H10: No | I10: 1043.63 | J10: 187.85 | K10: 0 | L10: 0 | M10: 0 | N10: Aug'26 | O10: 10/09/2026 | P10: Yes | R10: 100%
F11: =SUM(F7:F10) -> 7610.84 | G11: =SUM(G7:G10) -> 0 | H11: =SUM(H7:H10) -> 0 | I11: =SUM(I7:I10) -> 6679.31 | J11: =SUM(J7:J10) -> 827.39 | K11: =SUM(K7:K10) -> 52.07 | L11: =SUM(L7:L10) -> 52.07

Sheet B2B-CDNR
A1: Goods and Services Tax - GSTR-2B
A4: Debit/Credit notes (Original)
A5: GSTIN of supplier | B5: Trade/Legal name | C5: Credit note/Debit note details | H5: Place of supply | I5: Supply Attract Reverse Charge | J5: Taxable Value (₹) | K5: Tax Amount | O5: Whether ITC to be reduced (Taxpayer's Input) | P5: Amount declared by taxpayer for ITC reduction | T5: Remarks | U5: GSTR-1/IFF/1A/GSTR-5 Period | V5: GSTR-1/IFF/1A/GSTR-5 Filing Date | W5: ITC Availability | X5: Reason | Y5: Applicable % of Tax Rate | Z5: Source | AA5: IRN | AB5: IRN Date
C6: Note number | D6: Note type | E6: Note Supply type | F6: Note date | G6: Note Value (₹) | K6: Integrated Tax(₹) | L6: Central Tax(₹) | M6: State/UT Tax(₹) | N6: Cess(₹) | P6: Integrated Tax(₹) | Q6: Central Tax(₹) | R6: State/UT Tax(₹) | S6: Cess(₹)
A7: 29AAICA3918J1ZE | B7: AMAZON SELLER SERVICES PVT LTD | C7: KA-C-27-1254729 | D7: Credit Note | E7: Regular | F7: 31/08/2026 | G7: 106.2 | H7: Tamil Nadu | I7: No | J7: 90 | K7: 16.2 | L7: 0 | M7: 0 | N7: 0 | O7: NA | P7: NA | Q7: NA | R7: NA | S7: NA | T7: No remarks available | U7: Aug'26 | V7: 11/09/2026 | W7: Yes | Y7: 100%
A8: 29AAICA3918J1ZE | B8: AMAZON SELLER SERVICES PVT LTD | C8: KA-C-27-1254730 | D8: Credit Note | E8: Regular | F8: 31/08/2026 | G8: 177 | H8: Tamil Nadu | I8: No | J8: 150 | K8: 27 | L8: 0 | M8: 0 | N8: 0 | O8: NA | P8: NA | Q8: NA | R8: NA | S8: NA | T8: No remarks available | U8: Aug'26 | V8: 11/09/2026 | W8: Yes | Y8: 100%
A9: 29AACCF0683K1ZD | B9: FLIPKART INTERNET PRIVATE LIMITED | C9: FKCKA27000599775 | D9: Credit Note | E9: Regular | F9: 31/08/2026 | G9: 14.16 | H9: Tamil Nadu | I9: No | J9: 12 | K9: 2.16 | L9: 0 | M9: 0 | N9: 0 | O9: NA | P9: NA | Q9: NA | R9: NA | S9: NA | T9: No remarks available | U9: Aug'26 | V9: 10/09/2026 | W9: Yes | Y9: 100%
G10: =SUM(G7:G9) -> 297.36 | H10: =SUM(H7:H9) -> 0 | I10: =SUM(I7:I9) -> 0 | J10: =SUM(J7:J9) -> 252 | K10: =SUM(K7:K9) -> 45.36 | L10: =SUM(L7:L9) -> 0 | M10: =SUM(M7:M9) -> 0

Sheet SALES
C3: Sales- percentage Wise- B2CS | J3: Sales- State Wise
C5: PARTICULARS | D5: TAXABLE VALUE | E5: IGST | F5: CGST | G5: SGST | J5: TAX RATE | K5: TAXABLE VALUE | L5: IGST | M5: CGST | N5: SGST
B7: 0 | C7: Amazon- I/S | F7: 0 | G7: 0 | I7: Local | J7: 0 | K7: =+D8+D35 -> 0
C8: Amazon- Local | F8: 0 | G8: 0 | J8: 3 | K8: =+D11+D38 -> 0 | L8: =+E11+E38 -> 0 | M8: =+F11+F38 -> 0 | N8: =+G11+G38 -> 0
J9: 5 | K9: =+D14+D16+D18+D41 -> 21620.46 | L9: =+E14+E16+E18+E41 -> 0 | M9: =+F14+F16+F18+F41 -> 540.5115 | N9: =+G14+G16+G18+G41 -> 540.5115
B10: 0.03 | C10: Amazon- I/S | E10: =+D10*0.03 -> 0 | F10: 0 | G10: 0 | J10: 12 | K10: =+D21+D23+D25+D44 -> 0 | L10: =+E21+E23+E25 -> 0 | M10: =+F21+F23+F25 -> 0 | N10: =+G21+G23+G25 -> 0
C11: Amazon- Local | F11: =+D11*1.5% -> 0 | G11: =+F11 -> 0
B13: 0.05 | C13: Amazon- I/S | D13: ='State wise'!C26-SALES!D14 -> 7523.8 | E13: =+D13*0.05 -> 376.19 | F13: 0 | G13: 0 | I13: Interstate | J13: 0 | K13: =+D7+D34 -> 0 | L13: 0 | M13: 0 | N13: 0
C14: Amazon- Local | D14: ='State wise'!C23 -> 13633.32 | F14: =+D14*2.5% -> 340.833 | G14: =+F14 -> 340.833 | J14: 3 | K14: =+D10+D37 -> 0 | L14: =+E10+E37 -> 0 | M14: =+F10+F37 -> 0 | N14: =+G10+G37 -> 0
C15: Flipkart-I/s | D15: ='State wise'!D15-SALES!D16 -> 7380.58 | E15: =+D15*5% -> 369.029 | J15: 5 | K15: =+D13+D15+D17 -> 14904.38 | L15: =+E13+E15+E17 -> 745.219 | M15: =+F13+F15+F17 -> 0 | N15: =+G13+G15+G17 -> 0
C16: Flipkart-Local | D16: ='State wise'!D7 -> 4977.62 | F16: =+D16*2.5/100 -> 124.4405 | G16: =+F16 -> 124.4405 | J16: 12 | K16: =+D20+D22+D24+D43 -> 0 | L16: =+E20+E22+E24 -> 0 | M16: =+F20+F22+F24 -> 0 | N16: =+G20+G22+G24 -> 0
C17: Meeesho_I/s
C18: Meeesho_Local | F18: =+D18*2.5/100 -> 0 | G18: =+F18 -> 0 | K18: =SUM(K7:K17) -> 36524.84 | L18: =SUM(L7:L17) -> 745.219 | M18: =SUM(M7:M17) -> 540.5115 | N18: =SUM(N7:N17) -> 540.5115
B20: 0.12 | C20: Amazon- I/S | E20: =+D20*12% -> 0
C21: Amazon- Local | F21: =+D21*0.06 -> 0 | G21: =+F21 -> 0
C22: Flipkart-I/s | E22: =+D22*12% -> 0
C23: Flipkart-Local | F23: =+D23*6/100 -> 0 | G23: =+F23 -> 0
C24: Meesho_I/s | E24: =+D24*12% -> 0
C25: Meesho_Local | F25: =+D25*6/100 -> 0 | G25: =+F25 -> 0
D26: =SUM(D7:D25) -> 33515.32 | E26: =SUM(E7:E25) -> 745.219 | F26: =SUM(F7:F25) -> 465.2735 | G26: =SUM(G7:G25) -> 465.2735
C29: Sales- percentage Wise- B2B
C31: PARTICULARS | D31: TAXABLE VALUE | E31: IGST | F31: CGST | G31: SGST
B34: 0 | C34: Amazon- I/S | F34: 0 | G34: 0
C35: Amazon- Local | F35: =+D35*1.5% -> 0 | G35: =+F35 -> 0
B37: 0.03 | C37: Amazon- I/S | E37: =+D37*0.03 -> 0 | F37: 0 | G37: 0
C38: Amazon- Local | F38: =+D38*1.5% -> 0 | G38: =+F38 -> 0
B40: 0.05 | C40: Amazon- I/S | E40: =+D40*0.05 -> 0 | F40: 0 | G40: 0
C41: Amazon- Local | D41: =Amazon_B2b!F11 -> 3009.52 | F41: =+D41*2.5% -> 75.238 | G41: =+F41 -> 75.238
D42: .
B43: 0.12 | C43: Amazon- I/S | E43: =+D43*0.12 -> 0
C44: Amazon- Local | F44: =+D44*0.06 -> 0 | G44: =+F44 -> 0
D46: =SUM(D34:D44) -> 3009.52 | E46: =SUM(E34:E44) -> 0 | F46: =SUM(F34:F44) -> 75.238 | G46: =SUM(G34:G44) -> 75.238
C48: Consolidated
C50: PARTICULARS | D50: TAXABLE VALUE | E50: IGST | F50: CGST | G50: SGST
B51: 0 | C51: Amazon- I/S | D51: =+D34+D7 -> 0
C52: Amazon- Local | D52: =+D35+D8 -> 0
B54: 0.03 | C54: Amazon- I/S | D54: =+D10+D37 -> 0 | E54: =+E10+E37 -> 0 | F54: =+F10+F37 -> 0 | G54: =+G10+G37 -> 0
C55: Amazon- Local | D55: =+D11+D38 -> 0 | E55: =+E11+E38 -> 0 | F55: =+F11+F38 -> 0 | G55: =+G11+G38 -> 0
B57: 0.05 | C57: Amazon- I/S | D57: =+D13+D40 -> 7523.8 | E57: =+E13+E40 -> 376.19 | F57: =+F13+F40 -> 0 | G57: =+G13+G40 -> 0
C58: Amazon- Local | D58: =+D14+D41 -> 16642.84 | E58: =+E14+E41 -> 0 | F58: =+F14+F41 -> 416.071 | G58: =+G14+G41 -> 416.071
...

Sheet TAX CALCULATION
D2: PURCHASE
B3: PARTICULARS | C3: AMOUNT | D3: IGST | E3: CGST | F3: SGST | I3: MONTH | J3: IGST | K3: CGST | L3: SGST
I4: ITC | J4: 6478 | K4: 824 | L4: 824
B5: As per GSTR 2B | C5: =Input!I11 -> 6679.31 | D5: =Input!J11 -> 827.39 | E5: =Input!K11 -> 52.07 | F5: =Input!L11 -> 52.07 | I5: Input | J5: =D9 -> 782.03 | K5: =E9 -> 52.07 | L5: =F9 -> 52.07
B6: Less: Credit Note | C6: ='B2B-CDNR'!J10 -> 252 | D6: ='B2B-CDNR'!K10 -> 45.36 | E6: ='B2B-CDNR'!L10 -> 0 | F6: ='B2B-CDNR'!M10 -> 0 | J6: =ROUND(SUM(J4:J5),0) -> 7260 | K6: =SUM(K4:K5) -> 876.07 | L6: =SUM(L4:L5) -> 876.07 | M6: =ROUND(J6+K6+L6,0) -> 9012
B7: Add: Debit Note
I8: OUTPUT tax | J8: =ROUND(D16,0) -> 745 | K8: =ROUND(E16,0) -> 541 | L8: =ROUND(F16,0) -> 541
C9: =+C5-C6+C7 -> 6427.31 | D9: =D5-D6 -> 782.03 | E9: =+E5-E6+E7 -> 52.07 | F9: =+F5-F6+F7 -> 52.07
J10: =J8 -> 745 | K10: =K8 -> 541 | L10: =L8 -> 541
D11: SALES
B12: PARTICULARS | C12: AMOUNT | D12: IGST | E12: CGST | F12: SGST | I12: Tax to be Paid | J12: =J10 -> 745 | K12: =K10 -> 541 | L12: =L10 -> 541
B13: sales | C13: =+SALES!D70 -> 36524.84 | D13: =+SALES!E70 -> 745.219 | E13: =+SALES!F70 -> 540.5115 | F13: =+SALES!G70 -> 540.5115 | I13: Paid through Cash Ledger
I14: Paid through ITC Ledger-IGST | J14: =J12 -> 745 | K14: =K12 -> 541 | L14: =L12 -> 541 | M14: =J14+K14+L14 -> 1827
I15: Paid through ITC Ledger-CGST
C16: =SUM(C13:C15) -> 36524.84 | D16: =ROUND(SUM(D13:D15),0) -> 745 | E16: =ROUND(SUM(E13:E15),0) -> 541 | F16: =ROUND(SUM(F13:F15),0) -> 541 | I16: Paid through ITC Ledger-SGST
I17: ITC AVAILABLE | J17: =J14+K14+L14-J6 -> -5433 | K17: =ROUND(K15-K6,0) -> -876 | L17: =ROUND(L15-L6,0) -> -876 | M17: =+SUM(J17:L17) -> -7185
B19: TCS :
B20: Flipkart Internet Private Limited_ | I20: ITC: | J20: =+J6 -> 7260 | L20: =+L6 -> 876.07 | M20: ITC
B21: Amazon Seller Services_ 33AAICA3918J1C0 | C21: 24167 | I21: IGST Utilised in | K21: =+K14 -> 541 | L21: =+L14 -> 541
B22: Fashnear Technologies Pvt Ltd_33AACCF0683K1CZ | C22: 12358 | I22: CGST/SGST | K22: =+K15 -> 0 | L22: =+L16 -> 0
C23: =+SUM(C20:C22) -> 36525 | D23: =+SUM(D20:D22) -> 0 | E23: =+SUM(E20:E22) -> 0 | F23: =+SUM(F20:F22) -> 0
I24: Balance in ITC | J24: =+J20-SUM(J21:L21) -> 6178 | K24: =+K20-K22 -> 0 | L24: =+L20-L22 -> 876.07
B25: Difference
I26: Cash ledger- ITC
B27: Flipkart _TCS negative value | I27: Cash Ledger_October
J29: =ROUND(SUM(J26:J27),0) -> 0 | K29: =ROUND(SUM(K26:K27),0) -> 0 | L29: =ROUND(SUM(L26:L27),0) -> 0
I31: Balance in Cash Ledger | J31: 64 | K31: 68 | L31: 68
B32: GSTR 1 Filed | C32: =+C23+C30 -> 36525 | I32: Balance in ITC Ledger | J32: =J24 -> 6178 | K32: =K24 -> 0 | L32: =L24 -> 876.07 | M32: ITC

Sheet Amazon_B2b
B3: Amazon
B5: Invoice No | C5: Invoice Date | D5: Name of the Customer | E5: GST No. | F5: Tax Exclusive Gross | G5: Tax rate | H5: IGST | I5: CGST | J5: SGST | K5: Invoice Value
B6: IN-116 | C6: 46260.457 | D6: SREE VENKATESWARA AGENCIES | E6: 33AEWFS0631M1ZL | F6: 3009.52 | G6: 5 | I6: =F6*2.5/100 -> 75.238 | J6: =I6 -> 75.238 | K6: =F6+I6+J6 -> 3159.996
F11: =SUM(F6:F10) -> 3009.52 | H11: =SUM(H6:H10) -> 0 | I11: =SUM(I6:I10) -> 75.238 | J11: =SUM(J6:J10) -> 75.238 | K11: =SUM(K6:K10) -> 3159.996

Sheet State wise
B3: Flipkart
B6: Ship To State | C6: Invoice Amount | D6: Tax Exclusive Gross | E6: Tax Rate | F6: IGST | G6: CGST | H6: SGST
B7: TAMIL NADU Total | C7: =D7+G7+H7 -> 5226.48 | D7: 4977.62 | E7: 5 | F7: 0 | G7: 124.43 | H7: =G7 -> 124.43
B8: Kerala | C8: =D8+F8+G8+H8 -> 1968.14 | D8: 1874.42 | E8: 5 | F8: 93.72 | G8: 0 | H8: 0
B9: Karnataka | C9: =D9+F9+G9+H9 -> 629 | D9: 599.05 | E9: 5 | F9: 29.95 | G9: 0 | H9: 0
B10: Andhra Pradesh | C10: =D10+F10+G10+H10 -> 2111 | D10: 2010.47 | E10: 5 | F10: 100.53 | G10: 0 | H10: 0
B11: Himachal Pradesh | C11: =D11+F11+G11+H11 -> 462 | D11: 440 | E11: 5 | F11: 22 | G11: 0 | H11: 0
B12: Telangana | C12: =D12+F12+G12+H12 -> 2579.47 | D12: 2456.64 | E12: 5 | F12: 122.83 | G12: 0 | H12: 0
C15: =SUM(C7:C12) -> 12976.09 | D15: =SUM(D7:D12) -> 12358.2 | F15: =SUM(F7:F12) -> 369.03 | G15: =SUM(G7:G12) -> 124.43 | H15: =SUM(H7:H12) -> 124.43
B16: Amazon
B18: Ship To State | C18: Tax Exclusive Gross | D18: igst | E18: cgst | F18: sgst
B19: ANDHRA PRADESH Total | C19: 2257.14 | D19: =C19*5/100 -> 112.857 | E19: 0 | F19: 0
B20: KARNATAKA Total | C20: 752.38 | D20: =C20*5/100 -> 37.619 | E20: 0 | F20: 0
B21: KERALA Total | C21: 752.38 | D21: =C21*5/100 -> 37.619 | E21: 0 | F21: 0
B22: MAHARASHTRA Total | C22: 3009.52 | D22: =C22*5/100 -> 150.476 | E22: 0 | F22: 0
B23: TAMIL NADU Total | C23: 13633.32 | D23: 0 | E23: 340.84 | F23: =E23 -> 340.84 | G23: 16642.8
B24: TELANGANA Total | C24: 752.38 | D24: 37.619 | E24: 0 | F24: 0
B25: WEST BENGAL Total | E25: 0 | F25: 0
C26: =SUM(C19:C25) -> 21157.12 | D26: =SUM(D19:D25) -> 376.19 | E26: =SUM(E19:E25) -> 340.84 | F26: =SUM(F19:F25) -> 340.84

Sheet hsn Code
C2: Amazon | D2: B2b
D3: HSN CODE | E3: Quantity in Nos. | F3: Invoice Amount | G3: Tax Exclusive Gross | H3: Tax Rate | I3: IGST | J3: CGST | K3: SGST
D4: 4201 | E4: 4 | G4: 3009.52 | H4: 5 | J4: =G4*2.5/100 -> 75.238 | K4: =J4 -> 75.238
F7: =SUM(F4:F6) -> 0 | G7: =SUM(G4:G6) -> 3009.52 | I7: =SUM(I4:I6) -> 0 | J7: =SUM(J4:J6) -> 75.238 | K7: =SUM(K4:K6) -> 75.238
C9: Amazon | D9: B2CS
D11: Quantity | E11: Hsn/sac | F11: Ship To State | G11: Tax Exclusive Gross | H11: igst | I11: cgst | J11: sgst
D12: 29 | E12: 4201 Total | G12: =19561.88+847.62 -> 20409.5 | H12: 376.2 | I12: =21.19+300.96 -> 322.15 | J12: =I12 -> 322.15
D13: 2 | E13: 39269099 | G13: 747.62 | I13: 18.69 | J13: 18.69
D14: =SUM(D12:D12) -> 29 | F14: =SUM(F12:F12) -> 0 | G14: =SUM(G12:G13) -> 21157.12 | H14: =SUM(H12:H13) -> 376.2 | I14: =SUM(I12:I13) -> 340.84 | J14: =SUM(J12:J13) -> 340.84 | K14: SGST
C17: flipkart | D17: b2cs
D18: HSN CODE | E18: Quantity in Nos. | F18: Invoice Amount | G18: Tax Exclusive Gross | H18: Tax Rate | I18: IGST | J18: CGST | K18: sgst
D19: 7437 | E19: 15 | G19: 9518.95 | I19: 319.46 | J19: 78.23 | K19: 78.23
D20: 39269099 | E20: 6 | G20: 2839.25 | I20: 49.57 | J20: 46.19 | K20: 46.19
E22: =SUM(E19:E21) -> 21 | F22: =SUM(F19:F21) -> 0 | G22: =SUM(G19:G21) -> 12358.2 | H22: =SUM(H19:H21) -> 0 | I22: =SUM(I19:I21) -> 369.03 | J22: =SUM(J19:J21) -> 124.42 | K22: =SUM(K19:K21) -> 124.42

Sheet Document
E2: Amazon
E3: Invoice Series From | F3: Invoice Series To | G3: Total Number of Invoices | H3: Cancelled if any | I3: Net invoices Issued
E4: 96 | F4: 119 | G4: =F4-E4+1 -> 24 | H4: 7 | I4: =G4-H4 -> 17
E6: CREDIT NOTE
E7: CN-13 | F7: CN-16 | G7: 4
E9: Flipkart
E11: Invoice Series From | F11: Invoice Series To | G11: Total Number of Invoices | H11: Cancelled if any | I11: Net invoices Issued
E12: LWAB61V270000101 | F12: LWAB61V270000129 | G12: 29 | H12: 0 | I12: 29
C16: B2B BILL | D16: 116
C17: free replacement | D17: 103
C18: cancelled | D18: 107

Sheet Consolidated
A1: Ship To State | B1: Invoice Amount | C1: Tax Exclusive Gross | D1: Tax Rate | E1: IGST | F1: CGST | G1: SGST
A2: Andhra Pradesh | C2: 6287.46 | E2: 314.376 | F2: 0 | G2: 0
A3: Karnataka | C3: 10402.9 | E3: 520.133 | F3: 0 | G3: 0
A4: Kerala | C4: 4032.56 | E4: 201.628 | F4: 0 | G4: 0
A5: MAHARASHTRA | C5: 752.38 | E5: 37.619 | F5: 0 | G5: 0
A6: TAMIL NADU | C6: 22723.42 | E6: 0 | F6: 568.0855 | G6: 568.0855
A7: TELANGANA | C7: 752.38 | E7: 37.619 | F7: 0 | G7: 0
A8: WEST BENGAL | C8: 752.38 | E8: 37.619 | F8: 0 | G8: 0
C9: =SUM(C2:C8) -> 45703.48 | D9: =SUM(D2:D8) -> 0 | E9: =SUM(E2:E8) -> 1148.994 | F9: =SUM(F2:F8) -> 568.0855 | G9: =SUM(G2:G8) -> 568.0855

Sheet HSN Consolidated
D2: B2b
D3: HSN CODE | E3: Quantity in Nos. | F3: Invoice Amount | G3: Tax Exclusive Gross | H3: Tax Rate | I3: IGST | J3: CGST | K3: SGST
D4: 4201 | E4: 4 | G4: 3390 | J4: =G4*2.5/100 -> 84.75 | K4: =J4 -> 84.75
E7: =SUM(E4:E6) -> 4 | F7: =SUM(F4:F6) -> 0 | G7: =SUM(G4:G6) -> 3390 | I7: =SUM(I4:I6) -> 0 | J7: =SUM(J4:J6) -> 84.75 | K7: =SUM(K4:K6) -> 84.75
C9: B2CS
D10: Hsn/sac | E10: qty | F10: Tax Exclusive Gross | G10: igst | H10: cgst | I10: sgst
D11: 4201 | E11: 58 | F11: 42949.92 | G11: 1148.994 | H11: 499.2455 | I11: 499.2455
D12: 39269099 | E12: 5 | F12: 2753.64 | G12: 0 | H12: 68.83 | I12: 68.83
F13: =SUM(F11:F12) -> 45703.56 | G13: =SUM(G11:G12) -> 1148.994 | H13: =SUM(H11:H12) -> 568.0755 | I13: =SUM(I11:I12) -> 568.0755
