Workbook
Name Sheet_1_ListCol_1: [1]INTER!$A$8:$A$45

Sheet Input
A1: Goods and Services Tax - GSTR-2B
A4: Taxable inward supplies received from registered persons
A5: GSTIN of supplier | B5: Trade/Legal name | C5: Invoice Details | G5: Place of supply | H5: Supply Attract Reverse Charge | I5: Taxable Value (₹) | J5: Tax Amount | N5: GSTR-1/1A/IFF/GSTR-5 Period | O5: GSTR-1/1A/IFF/GSTR-5 Filing Date | P5: ITC Availability | Q5: Reason | R5: Applicable % of Tax Rate | S5: Source | T5: IRN | U5: IRN Date
C6: Invoice number | D6: Invoice type | E6: Invoice Date | F6: Invoice Value(₹) | J6: Integrated Tax(₹) | K6: Central Tax(₹) | L6: State/UT Tax(₹) | M6: Cess(₹)
A7: 29AARCM9332R1Z9 | B7: Meesho Technologies Private Limited | C7: MTI/0826/851986 | D7: Regular | E7: 31/08/2026 | F7: 86123.96 | G7: Tamil Nadu | H7: No | I7: 72986.41 | J7: 13137.55 | K7: 0 | L7: 0 | M7: 0 | N7: Aug'26 | O7: 11/09/2026 | P7: Yes | R7: 100%
A8: 33AJXPR7758N1ZX | B8: M.R.TEX | C8: 149 | D8: Regular | E8: 15/08/2026 | F8: 29400 | G8: Tamil Nadu | H8: No | I8: 28000 | J8: 0 | K8: 700 | L8: 700 | M8: 0 | N8: Aug'26 | O8: 11/09/2026 | P8: Yes | R8: 100%
A9: 33AALHS5608H1Z0 | B9: SIVAMANIHUF SRI SIVAMANI TEXTILES | C9: 59 | D9: Regular | E9: 24/08/2026 | F9: 132032 | G9: Tamil Nadu | H9: No | I9: 125745.2 | J9: 0 | K9: 3143.63 | L9: 3143.63 | M9: 0 | N9: Aug'26 | O9: 08/09/2026 | P9: Yes | R9: 100%
A10: 29AAICA3918J1ZE | B10: AMAZON SELLER SERVICES PVT LTD | C10: 26-WMM-396239 | D10: Regular | E10: 19/08/2026 | F10: 2531.15 | G10: Tamil Nadu | H10: No | I10: 2145.05 | J10: 386.1 | K10: 0 | L10: 0 | M10: 0 | N10: Aug'26 | O10: 11/09/2026 | P10: Yes | R10: 100%
A11: 29AAICA3918J1ZE | B11: AMAZON SELLER SERVICES PVT LTD | C11: ADS-2627-373314 | D11: Regular | E11: 31/08/2026 | F11: 45636.87 | G11: Tamil Nadu | H11: No | I11: 38675.38 | J11: 6961.49 | K11: 0 | L11: 0 | M11: 0 | N11: Aug'26 | O11: 11/09/2026 | P11: Yes | R11: 100%
A12: 29AAICA3918J1ZE | B12: AMAZON SELLER SERVICES PVT LTD | C12: KA-2627-1658301 | D12: Regular | E12: 31/08/2026 | F12: 14168.26 | G12: Tamil Nadu | H12: No | I12: 12007 | J12: 2161.26 | K12: 0 | L12: 0 | M12: 0 | N12: Aug'26 | O12: 11/09/2026 | P12: Yes | R12: 100%
A13: 29AAICA3918J1ZE | B13: AMAZON SELLER SERVICES PVT LTD | C13: KA-2627-1687502 | D13: Regular | E13: 31/08/2026 | F13: 29730.1 | G13: Tamil Nadu | H13: No | I13: 25195 | J13: 4535.1 | K13: 0 | L13: 0 | M13: 0 | N13: Aug'26 | O13: 11/09/2026 | P13: Yes | R13: 100%
A14: 29AALCV8310J1ZU | B14: VALMO TRANSPORTATION PRIVATE LIMITED | C14: VTI/0826/637850 | D14: Regular | E14: 31/08/2026 | F14: 2973.93 | G14: Tamil Nadu | H14: No | I14: 2832.31 | J14: 141.62 | K14: 0 | L14: 0 | M14: 0 | N14: Aug'26 | O14: 11/09/2026 | P14: Yes | R14: 100%
A15: 33BEKPM1129P1Z8 | B15: S. MALATHI PROP B. T. C. FABRICS | C15: 742 | D15: Regular | E15: 12/08/2026 | F15: 14011 | G15: Tamil Nadu | H15: No | I15: 13344 | J15: 0 | K15: 333.6 | L15: 333.6 | M15: 0 | N15: Aug'26 | O15: 08/09/2026 | P15: Yes | R15: 100%
A16: 29AACCF0683K1ZD | B16: FLIPKART INTERNET PRIVATE LIMITED | C16: FKRKA27001094387 | D16: Regular | E16: 31/08/2026 | F16: 17189.66 | G16: Tamil Nadu | H16: No | I16: 14567.49 | J16: 2622.15 | K16: 0 | L16: 0 | M16: 0 | N16: Aug'26 | O16: 10/09/2026 | P16: Yes | R16: 100%
A17: 33AHXPS4897D1ZK | B17: SUBRAMANI TEXTILES | C17: 1014 | D17: Regular | E17: 29/08/2026 | F17: 6300 | G17: Tamil Nadu | H17: No | I17: 6000 | J17: 0 | K17: 150 | L17: 150 | M17: 0 | N17: Aug'26 | O17: 05/09/2026 | P17: Yes | R17: 100%
A18: 33AHXPS4897D1ZK | B18: SUBRAMANI TEXTILES | C18: 863 | D18: Regular | E18: 14/08/2026 | F18: 52448 | G18: Tamil Nadu | H18: No | I18: 49950 | J18: 0 | K18: 1248.75 | L18: 1248.75 | M18: 0 | N18: Aug'26 | O18: 05/09/2026 | P18: Yes | R18: 100%
... A21: 29AACCF6368D1ZI | B21: MEESHO LIMITED | C21: MLI/0826/1060791 | D21: Regular | E21: 31/08/2026 | F21: 83896.29 | G21: Tamil Nadu | H21: No | I21: 71098.55 | J21: 12797.74 | K21: 0 | L21: 0 | M21: 0 | N21: Aug'26 | O21: 11/09/2026 | P21: Yes | R21: 100%
F22: =SUM(F7:F21) -> 540381.22 | G22: =SUM(G7:G21) -> 0 | H22: =SUM(H7:H21) -> 0 | I22: =SUM(I7:I21) -> 485346.39 | J22: =SUM(J7:J21) -> 42743.01 | K22: =SUM(K7:K21) -> 6145.98 | L22: =SUM(L7:L21) -> 6145.98

Sheet Credit Note
A1: Goods and Services Tax - GSTR-2B
A4: Debit/Credit notes (Original)
A5: GSTIN of supplier | B5: Trade/Legal name | C5: Credit note/Debit note details | H5: Place of supply | I5: Supply Attract Reverse Charge | J5: Taxable Value (₹) | K5: Tax Amount | O5: Whether ITC to be reduced (Taxpayer's Input) | P5: Amount declared by taxpayer for ITC reduction | T5: Remarks | U5: GSTR-1/IFF/1A/GSTR-5 Period | V5: GSTR-1/IFF/1A/GSTR-5 Filing Date | W5: ITC Availability | X5: Reason | Y5: Applicable % of Tax Rate | Z5: Source | AA5: IRN | AB5: IRN Date
C6: Note number | D6: Note type | E6: Note Supply type | F6: Note date | G6: Note Value (₹) | K6: Integrated Tax(₹) | L6: Central Tax(₹) | M6: State/UT Tax(₹) | N6: Cess(₹) | P6: Integrated Tax(₹) | Q6: Central Tax(₹) | R6: State/UT Tax(₹) | S6: Cess(₹)
A7: 29AAICA3918J1ZE | B7: AMAZON SELLER SERVICES PVT LTD | C7: KA-C-27-1133706 | D7: Credit Note | E7: Regular | F7: 31/08/2026 | G7: 637.2 | H7: Tamil Nadu | I7: No | J7: 540 | K7: 97.2 | L7: 0 | M7: 0 | N7: 0 | O7: NA | P7: NA | Q7: NA | R7: NA | S7: NA | T7: No remarks available | U7: Aug'26 | V7: 11/09/2026 | W7: Yes | Y7: 100%
A8: 29AAICA3918J1ZE | B8: AMAZON SELLER SERVICES PVT LTD | C8: KA-C-27-1133709 | D8: Credit Note | E8: Regular | F8: 31/08/2026 | G8: 1229.56 | H8: Tamil Nadu | I8: No | J8: 1042 | K8: 187.56 | L8: 0 | M8: 0 | N8: 0 | O8: NA | P8: NA | Q8: NA | R8: NA | S8: NA | T8: No remarks available | U8: Aug'26 | V8: 11/09/2026 | W8: Yes | Y8: 100%
A9: 29AACCF0683K1ZD | B9: FLIPKART INTERNET PRIVATE LIMITED | C9: FKCKA27000561745 | D9: Credit Note | E9: Regular | F9: 31/08/2026 | G9: 78.62 | H9: Tamil Nadu | I9: No | J9: 66.63 | K9: 11.99 | L9: 0 | M9: 0 | N9: 0 | O9: NA | P9: NA | Q9: NA | R9: NA | S9: NA | T9: No remarks available | U9: Aug'26 | V9: 10/09/2026 | W9: Yes | Y9: 100%
G10: =SUM(G7:G9) -> 1945.38 | H10: =SUM(H7:H9) -> 0 | I10: =SUM(I7:I9) -> 0 | J10: =SUM(J7:J9) -> 1648.63 | K10: =SUM(K7:K9) -> 296.75 | L10: =SUM(L7:L9) -> 0 | M10: =SUM(M7:M9) -> 0

Sheet SALES
C3: Sales- percentage Wise- B2CS | K3: Sales- State Wise
C5: PARTICULARS | D5: TAXABLE VALUE | E5: IGST | F5: CGST | G5: SGST | K5: TAX RATE | L5: TAXABLE VALUE | M5: IGST | N5: CGST | O5: SGST
B7: 0.03 | C7: Meesho_I/s | F7: =D7*1.5/100 -> 0 | G7: =+F7 -> 0
B14: 0.05 | C14: Amazon- I/S | D14: ='Company Wise Sales'!D29-'Company Wise Sales'!D24 -> 128938.53 | E14: =D14*5/100 -> 6446.9265 | J14: Local | K14: 5 | L14: =D15+D17+D19+D21+D23+D25 -> 173323.32
C15: Amazon- Local | D15: ='Company Wise Sales'!D24 -> 29092.76 | F15: =D15*2.5/100 -> 727.319 | G15: =F15 -> 727.319 | K15: 12
C16: Flipkart_I/s | D16: ='Company Wise Sales'!D59-'Company Wise Sales'!D32 -> 112404.55 | E16: =D16*5/100 -> 5620.2275
C17: Flipkart_Local | D17: ='Company Wise Sales'!D32 -> 22682.62 | F17: =+D17*B14/2 -> 567.0655 | G17: =+F17 -> 567.0655
C18: Meesho_I/s | D18: ='Company Wise Sales'!B102-SALES!D19 -> 411122.09 | E18: =+D18*5/100 -> 20556.105
C19: Meesho_Local | D19: ='Company Wise Sales'!B96 -> 121547.94 | F19: =+D19*B14/2 -> 3038.6985 | G19: =+F19 -> 3038.6985 | J19: Interstate | K19: 5 | L19: =D14+D16+D18+D20+D22+D24+D39 -> 655703.75
C20: Reliance_I/s | E20: =+D20*0.05 -> 0 | F20: 0 | G20: 0 | K20: 12 | L20: =D29 -> 0
C21: Reliance_Local | F21: =+D21*2.5% -> 0 | G21: =+F21 -> 0
C22: Glowroad_I/s | E22: =+D22*0.05 -> 0
C23: Glowroad_Local | F23: =+D23*2.5/100 -> 0 | G23: =+F23 -> 0
C24: AJIO_I/s | E24: =D24*5/100 -> 0
C25: Ajio_local | F25: =D25*2.5/100 -> 0 | G25: =F25 -> 0
B29: 0.12 | C29: Meesho_I/s | E29: =+D29*B29 -> 0 | L29: =ROUND(SUM(L14:L28),0) -> 829027 | M29: =ROUND(SUM(M14:M28),0) -> 0 | N29: =ROUND(SUM(N14:N21),0) -> 0 | O29: =+N29 -> 0
C30: Meesho_Local | F30: =+D30*B29/2 -> 0 | G30: =+F30 -> 0
D31: =SUM(D7:D30) -> 825788.49 | E31: =SUM(E7:E30) -> 32623.259 | F31: =SUM(F7:F30) -> 4333.083 | G31: =SUM(G7:G30) -> 4333.083
C34: Sales- percentage Wise- B2B
C36: PARTICULARS | D36: TAXABLE VALUE | E36: IGST | F36: CGST | G36: SGST
B39: 0.05 | C39: Amazon- I/S | D39: =B2B!F5+B2B!F6+B2B!F7+B2B!F8 -> 3238.58 | E39: =+D39*5% -> 161.929
C40: Amazon- Local | D40: =B2B!F9 -> 414.29 | F40: =D40*2.5/100 -> 10.35725 | G40: =F40 -> 10.35725
C41: Merchant_Local | F41: =+D41*2.5/100 -> 0 | G41: =+F41 -> 0
D44: =SUM(D39:D43) -> 3652.87 | E44: =SUM(E39:E43) -> 161.929 | F44: =SUM(F39:F43) -> 10.35725 | G44: =SUM(G39:G43) -> 10.35725
C46: Consolidated
C48: PARTICULARS | D48: TAXABLE VALUE | E48: IGST | F48: CGST | G48: SGST
B49: 0.05 | D49: =+SUM(D14:D25)+SUM(D39:D43)+SUM(D7:D9) -> 829441.36 | E49: =+SUM(E14:E25)+SUM(E39:E43)+SUM(E7:E9) -> 32785.188 | F49: =+SUM(F14:F25)+SUM(F39:F43)+SUM(F7:F9) -> 4343.4402 | G49: =+SUM(G14:G25)+SUM(G39:G43)+SUM(G7:G9) -> 4343.4402
B52: 0.12 | D52: =+SUM(D29:D30) -> 0 | E52: =+SUM(E29:E30) -> 0 | F52: =+SUM(F29:F30) -> 0 | G52: =+SUM(G29:G30) -> 0
D54: =+SUM(D49:D53) -> 829441.36 | E54: =+SUM(E49:E53) -> 32785.188 | F54: =+SUM(F49:F53) -> 4343.4402 | G54: =+SUM(G49:G53) -> 4343.4402
C57: B2B | D57: =D44 -> 3652.87 | E57: =E44 -> 161.929 | F57: =F44 -> 10.35725 | G57: =G44 -> 10.35725
C58: B2CS | D58: =D31 -> 825788.49 | E58: =E31 -> 32623.259 | F58: =F31 -> 4333.083 | G58: =G31 -> 4333.083

Sheet TAX CALCULATION
D4: PURCHASE
B5: PARTICULARS | C5: AMOUNT | D5: IGST | E5: CGST | F5: SGST | I5: MONTH | J5: IGST | K5: CGST | L5: SGST
I6: ITC | J6: 1016066 | K6: 578157 | L6: 578157
B7: As per Sheet" Input Invoice" | C7: =Input!I22 -> 485346.39 | D7: =Input!J22 -> 42743.01 | E7: =Input!K22 -> 6145.98 | F7: =Input!L22 -> 6145.98 | I7: Input | J7: =ROUND(D11,0) -> 42446 | K7: =ROUND(E11,0) -> 6146 | L7: =ROUND(F11,0) -> 6146 | M7: =J7-J8 -> 42446
B8: Less: Credit Note | C8: ='Credit Note'!J10 -> 1648.63 | D8: ='Credit Note'!K10 -> 296.75 | E8: ='Credit Note'!L10 -> 0 | F8: ='Credit Note'!M10 -> 0
B9: Add: Debit Note | J9: =SUM(J5:J7)-J8 -> 1058512 | K9: =SUM(K5:K7) -> 584303 | L9: =SUM(L5:L7) -> 584303 | M9: =J9+K9+L9 -> 2227118
C11: =+C7-C8 -> 483697.76 | D11: =+D7-D8+D9 -> 42446.26 | E11: =+E7-E8+E9 -> 6145.98 | F11: =+F7-F8+F9 -> 6145.98 | I11: OUTPUT tax | J11: =+D18 -> 32785.188 | K11: =+E18 -> 4343.4402 | L11: =+F18 -> 4343.4402
D13: SALES | J13: =J11 -> 32785.188 | K13: =ROUND(K11,0) -> 4343 | L13: =ROUND(L11,0) -> 4343
B14: PARTICULARS | C14: AMOUNT | D14: IGST | E14: CGST | F14: SGST | G14: Invoice Value
I15: Tax to be Paid | J15: =ROUND(J13,0) -> 32785 | K15: =ROUND(K13,0) -> 4343 | L15: =ROUND(L13,0) -> 4343
B16: Sales | C16: =SALES!D54 -> 829441.36 | D16: =SALES!E54 -> 32785.188 | E16: =SALES!F54 -> 4343.4402 | F16: =SALES!G54 -> 4343.4402 | I16: Adjustment: CASH LEDGER
B17: ROUND OFF | I17: Adjustment: IGST | J17: =+J15-J16 -> 32785 | K17: =+K15-K16 -> 4343 | L17: =+L15-L16 -> 4343
C18: =SUM(C15:C17) -> 829441.36 | D18: =D16-D17 -> 32785.188 | E18: =E16+E17 -> 4343.4402 | F18: =F16+F17 -> 4343.4402 | I18: Adjustment: CGST
I19: Adjustment: SGST
D20: Cash Ledger | I20: To be Paid | J20: =+J15-SUM(J16:J19) -> 0 | K20: =+K15-SUM(K16:K19) -> 0 | L20: =+L15-SUM(L16:L19) -> 0 | M20: =ROUND(SUM(J20:L20),0) -> 0
B21: PARTICULARS | C21: AMOUNT | D21: IGST | E21: CGST | F21: SGST | I21: ITC | J21: =ROUND(J9-SUM(J17:L17),0) -> 1017041 | K21: =+K9-K18-J18 -> 584303 | L21: =+L9-L19-J19 -> 584303 | M21: ITC
B22: JANUARY | I22: LATE FEE | M22: =+K22+L22 -> 0
B23: Meesho -33AARCM9332R1CV | C23: 532670.1 | I23: Interest
B24: Sociofy ( Glowroad )
B25: Flipkart-33AACCF0683K1CZ | C25: 135212 | I25: ITC IN Cash Ledger | J25: 16156 | K25: 2035 | L25: 2035
B26: Amazon-33AAICA3918J1C0 | C26: 161684 | I26: Cash Ledger(October) | J26: =+ROUND(D30,0) -> 0 | K26: =+ROUND(E30,0) -> 0 | L26: =+ROUND(F30,0) -> 0
B27: Sppin India-33ABGCS4054E1CW | I27: Total Cash ledger | J27: =ROUND(J25+J26,0) -> 16156 | K27: =ROUND(K25+K26,0) -> 2035 | L27: =ROUND(L25+L26,0) -> 2035
B28: Reliance Retail-33AABCR1718E1C7 | I28: Utilised in Month | J28: =J16 -> 0 | K28: =K16 -> 0 | L28: =L16 -> 0
I29: ITC IN CASH LEDGER | J29: =+J27-J28 -> 16156 | K29: =+K27-K28 -> 2035 | L29: =+L27-L28 -> 2035
C30: =SUM(C23:C29) -> 829566.1 | D30: =SUM(D23:D29) -> 0 | E30: =SUM(E23:E29) -> 0 | F30: =SUM(F23:F29) -> 0 | G30: ………………..
I32: TAX PAID
I33: late fees | M33: =K33+L33 -> 0
A36: Note
B39: Difference during the month | D39: =+C30-C18 -> 124.73667
B41: Reconcilation
B43: Ajio Report Not updated in TCS Portal
B45: Amazon | C45: =C26-B2B!F12-'Company Wise Sales'!D29 -> -0.16
B46: Round off diff
B47: MEESHO | C47: =C23-'Company Wise Sales'!B102 -> 0.066666668
B48: Total | C48: =SUM(C45:C47) -> -0.093333332 | D48: =+SUM(D43:D46) -> 0
B49: Negative Amount not shown in TCS Return
B50: Flipkart | D50: =C25-'Company Wise Sales'!D59 -> 124.83
B66: SSS NOVELTIES Multi Color Cotton Checkered Lungi for Men s Combo of 2 Size 2 25meters Lungis | C66: 610510
B67: SSS Novelties Pure Baby Soft Quick Absorbency Cotton 100 Tc Bath Towels 30 Inches X 60 Inches White Pack of 6 | C67: 61119090

Sheet B2B
A2: AMAZON_B2b
A4: Invoice Number | B4: Invoice Date | C4: Buyer Name | D4: GST No. | E4: Invoice Amount | F4: Tax Exclusive Gross | G4: Tax rate | H4: Igst Tax | I4: Cgst Tax | J4: Sgst Tax | K4: Ship To State | L4: Credit Note No | M4: Credit Note Date
A5: IN-1240 | B5: 46259.755 | C5: ALISHAN INTERIORS | D5: 07AEWPA4413K1ZD | E5: =F5+H5+I5+J5 -> 495.5055 | F5: 471.91 | G5: 5 | H5: =F5*5/100 -> 23.5955
A6: IN-1274 | B6: 46263.717 | C6: SEJAL AYURVEDA | D6: 23BPRPP6657M1ZZ | E6: =F6+H6+I6+J6 -> 1584.492 | F6: 1509.04 | H6: =F6*5/100 -> 75.452
A7: IN-997 | B7: 46236.952 | C7: EXOTIC CIRCLE | D7: 27ALCPB4119N1Z6 | E7: =F7+H7+I7+J7 -> 924.9975 | F7: 880.95 | G7: 5 | H7: =F7*5/100 -> 44.0475
A8: IN-1213 | B8: 46254.932 | C8: M s MALHAR MEDICAL AND GENERAL STORE | D8: 27APDPG5785L1ZE | E8: =F8+H8+I8+J8 -> 395.514 | F8: 376.68 | G8: 5 | H8: =F8*5/100 -> 18.834
A9: IN-1159 | B9: 46250.069 | C9: INFONET COMM ENTERPRISES PRIVATE LIMITED | D9: 33AACCM8749D1ZH | E9: =F9+H9+I9+J9 -> 435.0045 | F9: 414.29 | G9: 5 | I9: =F9*2.5/100 -> 10.35725 | J9: =I9 -> 10.35725
E12: =SUM(E5:E11) -> 3835.5135 | F12: =SUM(F5:F11) -> 3652.87 | H12: =SUM(H5:H11) -> 161.929 | I12: =SUM(I5:I11) -> 10.35725 | J12: =SUM(J5:J11) -> 10.35725
A13: FLIPKART
A14: Invoice Number | B14: Invoice Date | C14: Buyer Name | D14: GST No. | E14: Invoice Amount | F14: Tax Exclusive Gross | G14: Tax rate | H14: Igst Tax | I14: Cgst Tax | J14: Sgst Tax | K14: Ship To State | L14: Credit Note No | M14: Credit Note Date

Sheet Company Wise Sales
B3: AMAZON
B4: Ship To State | C4: Invoice Amount | D4: Tax Exclusive Gross | E4: igst | F4: cgst | G4: sgst
B5: ANDHRA PRADESH | D5: 15845.79 | E5: 792.2895 | F5: 0 | G5: 0
B6: ASSAM | D6: 1621.9 | E6: 81.095 | F6: 0 | G6: 0
B7: BIHAR | D7: 6254.29 | E7: 312.7145 | F7: 0 | G7: 0
B8: CHHATTISGARH | D8: 2157.14 | E8: 107.857 | F8: 0 | G8: 0
B9: DELHI | D9: 3742.86 | E9: 187.143 | F9: 0 | G9: 0
B10: GOA | D10: 578.1 | E10: 28.905 | F10: 0 | G10: 0
B11: GUJARAT | D11: 3282.85 | E11: 164.1425 | F11: 0 | G11: 0
B12: HARYANA | D12: 2450.47 | E12: 122.5235 | F12: 0 | G12: 0
B13: HIMACHAL PRADESH | D13: 713.33 | E13: 35.6665 | F13: 0 | G13: 0
B14: JHARKHAND | D14: 2095.24 | E14: 104.762 | F14: 0 | G14: 0
B15: KARNATAKA | D15: 19398.22 | E15: 969.911 | F15: 0 | G15: 0
B16: KERALA | D16: 19936.34 | E16: 996.817 | F16: 0 | G16: 0
... B28: WEST BENGAL | D28: 6251.42 | E28: 312.571 | F28: 0 | G28: 0
D29: =SUM(D5:D28) -> 158031.29 | E29: =SUM(E5:E28) -> 6446.9265 | F29: =SUM(F5:F28) -> 727.319 | G29: =SUM(G5:G28) -> 727.319
B31: FLIPKART
B32: TAMIL NADU | D32: 22682.62 | F32: =D32*2.5/100 -> 567.0655 | G32: =F32 -> 567.0655
B33: Madhya Pradesh | D33: 1729.9 | E33: 86.47
B34: Maharashtra | D34: 5978.5 | E34: 298.91
B35: Andhra Pradesh | D35: 12341.62 | E35: 617.05
B36: Bihar | D36: 4130.19 | E36: 206.49
B37: Dadra and Nagar Haveli | D37: 569.11 | E37: 28.45
B38: Jharkhand | D38: 499.47 | E38: 24.97
B39: Pondicherry | D39: 496.19 | E39: 24.81
B40: Karnataka | D40: 12170.29 | E40: 608.51
B41: Delhi | D41: 966.2 | E41: 48.3
B42: Tripura | D42: -121.12 | E42: -6.06
B43: Haryana | D43: 425.71 | E43: 21.29
B44: Goa | D44: 855.47 | E44: 42.75
... B57: Gujarat | D57: 1387.61 | E57: 69.38
D59: =SUM(D32:D58) -> 135087.17 | E59: =SUM(E32:E58) -> 5620 | F59: =SUM(F32:F58) -> 567.0655 | G59: =SUM(G32:G58) -> 567.0655 | H59: =SUM(H32:H58) -> 0
B62: MEESHO
B63: _taxable_sale_value | C63: IGST | D63: CGST | E63: SGST | F63: end_customer_state_new
B64: 2573.5238 | C64: 128.67619 | D64: 0 | E64: 0 | F64: ANDAMAN & NICOBAR ISLANDS
B65: -768.57143 | C65: -38.428571 | D65: 0 | E65: 0 | F65: Andaman and Nicobar Islands
B66: 50992.13 | C66: 2549.6065 | D66: 0 | E66: 0 | F66: ANDHRA PRADESH
B67: 357.71429 | C67: 17.885714 | D67: 0 | E67: 0 | F67: ARUNACHAL PRADESH
B68: 13956.593 | C68: 697.82967 | D68: 0 | E68: 0 | F68: ASSAM
B69: 36222.711 | C69: 1811.1356 | D69: 0 | E69: 0 | F69: BIHAR
...

Sheet conso sales
A1: Ship To State | B1: Tax Exclusive Gross | C1: igst | D1: cgst | E1: sgst
A2: Andaman and Nicobar Islands | B2: 1804.9524 | C2: 90.247619 | D2: 0 | E2: 0
A3: Andhra Pradesh | B3: 79179.54 | C3: 3958.946 | D3: 0 | E3: 0
A4: ARUNACHAL PRADESH | B4: 357.71429 | C4: 17.885714 | D4: 0 | E4: 0
A5: Assam | B5: 20352.683 | C5: 1017.6647 | D5: 0 | E5: 0
A6: Bihar | B6: 46607.191 | C6: 2330.3401 | D6: 0 | E6: 0
A7: CHANDIGARH | B7: 383.0381 | C7: 19.151905 | D7: 0 | E7: 0
A8: CHATTISGARH | B8: 8585.9371 | C8: 429.29986 | D8: 0 | E8: 0
A9: Dadra & Nagar Haveli & Daman & Diu | B9: 1182.4471 | C9: 59.116857 | D9: 0 | E9: 0
A10: Delhi | B10: 7413.8124 | C10: 370.68062 | D10: 0 | E10: 0
A11: Goa | B11: 2429.9414 | C11: 121.47357 | D11: 0 | E11: 0
A12: Gujarat | B12: 13480.885 | C12: 674.04376 | D12: 0 | E12: 0
A13: Haryana | B13: 6564.7419 | C13: 328.2416 | D13: 0 | E13: 0
... A35: West Bengal | B35: 59050.32 | C35: 2952.5225 | D35: 0 | E35: 0
B36: =SUM(B2:B35) -> 825788.49 | C36: =SUM(C2:C35) -> 32623.031 | D36: =SUM(D2:D35) -> 4333.083 | E36: =SUM(E2:E35) -> 4333.083

Sheet HSN CODE
A2: b2b
A3: Amazon
B4: hsn | C4: qty | D4: taxable value | E4: igst | F4: cgst | G4: sgast
B5: 6109 | C5: 1 | D5: 376.68 | E5: 18.834 | F5: 0 | G5: 0
B6: 610510 | C6: 3 | D6: 1767.15 | E6: 67.643 | F6: 10.35725 | G6: 10.35725
B7: 52092910 | C7: 2 | D7: 1509.04 | E7: 75.452 | F7: 0 | G7: 0
C8: =SUM(C5:C7) -> 6 | D8: =SUM(D5:D7) -> 3652.87 | E8: =SUM(E5:E7) -> 161.929 | F8: =SUM(F5:F7) -> 10.35725 | G8: =SUM(G5:G7) -> 10.35725
A10: B2CS
A11: Amazon
B12: qty | C12: hsn | F12: taxable vlaue | G12: igst | H12: cgst | I12: sgst
B13: 4 | C13: 6109 | F13: 1536.2 | G13: 56.81 | H13: 10 | I13: 10
B14: 233 | C14: 610510 | F14: 131500.61 | G14: 5490.8265 | H14: 542.102 | I14: 542.102
B15: 3 | C15: 52082110 | F15: 1131.44 | G15: 38.048 | H15: 9.262 | I15: 9.262
B16: 14 | C16: 52082210 | F16: 5702 | G16: 163.192 | H16: 60.954 | I16: 60.954
B17: 13 | C17: 52083110 | F17: 6600 | G17: 303.809 | H17: 13.0955 | I17: 13.0955
B18: 2 | C18: 52083210 | F18: 961.88 | G18: 0 | H18: 24.047 | I18: 24.047
B19: 19 | C19: 52092910 | F19: 9846.78 | G19: 356.622 | H19: 67.8585 | I19: 67.8585
B20: 2 | C20: 61119090 | F20: 752.38 | G20: 37.619 | H20: 0 | I20: 0
B21: =SUM(B13:B20) -> 290 | F21: =SUM(F13:F20) -> 158031.29 | G21: =SUM(G13:G20) -> 6446.9265 | H21: =SUM(H13:H20) -> 727.319 | I21: =SUM(I13:I20) -> 727.319
A24: FLIPKART
B25: qty | C25: hsn | F25: taxable vlaue | G25: igst | H25: cgst | I25: sgst
B26: 501 | C26: 52083210 | F26: 135087.17 | G26: 5620 | H26: 567.04 | I26: 567.04
B28: =SUM(B26:B27) -> 501 | C28: =SUM(C26:C27) -> 0 | D28: =SUM(D26:D27) -> 0 | E28: =SUM(E26:E27) -> 0 | F28: =SUM(F26:F27) -> 135087.17 | G28: =SUM(G26:G27) -> 5620 | H28: =SUM(H26:H27) -> 567.04 | I28: =SUM(I26:I27) -> 567.04
A31: MEESHO
B32: qty | C32: hsn | F32: taxable vlaue | G32: igst | H32: cgst | I32: sgst
B33: 1 | C33: 3926 | F33: 373.33333 | G33: 18.666667 | H33: 0 | I33: 0
B34: 649 | C34: 6211 | F34: 183643.68 | G34: 7911.0842 | H34: 635.54981 | I34: 635.54981
B35: 2 | C35: 6302 | F35: 673.33333 | G35: 33.666667 | H35: 0 | I35: 0
B36: 2 | C36: 6304 | F36: 807.13333 | G36: 40.356667 | H36: 0 | I36: 0
B37: 1 | C37: 580610 | F37: -570.54286 | G37: -55.093333 | H37: 13.283095 | I37: 13.283095
B38: 142 | C38: 611420 | F38: 39204.903 | G38: 1637.128 | H38: 161.55857 | I38: 161.55857
B39: 3 | C39: 620920 | F39: 1201.6952 | G39: 42.428571 | H39: 8.8280952 | I39: 8.8280952
B40: 825 | C40: 621132 | F40: 300993.73 | G40: 10732.3 | H40: 2158.6932 | I40: 2158.6932
B41: 6 | C41: 621133 | F41: 1570.8381 | G41: 64.684762 | H41: 6.9285714 | I41: 6.9285714
B42: 0 | C42: 621139 | F42: -77.142857 | G42: -27.619048 | H42: 11.880952 | I42: 11.880952
B43: 2 | C43: 630260 | F43: 987.61905 | G43: 27.238095 | H43: 11.071429 | I43: 11.071429
B44: 1 | C44: 630419 | F44: 506.66667 | G44: 25.333333 | H44: 0 | I44: 0
B45: 11 | C45: 630492 | F45: 3354.7905 | G45: 105.93 | H45: 30.904762 | I45: 30.904762
B46: =SUM(B33:B45) -> 1645 | C46: =SUM(C33:C45) -> 5590268 | D46: =SUM(D33:D45) -> 0 | E46: =SUM(E33:E45) -> 0 | F46: =SUM(F33:F45) -> 532670.03 | G46: =SUM(G33:G45) -> 20556.105 | H46: =SUM(H33:H45) -> 3038.6985 | I46: =SUM(I33:I45) -> 3038.6985

Sheet Documents
B3: name of the Company | C3: Invoice Series From | D3: Invoice Series To | E3: Total Number of Invoices | F3: Cancelled if any | G3: Net invoices Issued
B4: AMAZON | C4: IN-983 | D4: IN-1301 | E4: =1301-983+1 -> 319 | F4: 117 | G4: =E4-F4 -> 202
B5: FLIPKART | C5: LWABM4B270001703 | D5: LWABM4B270002367 | E5: 665 | F5: 0 | G5: 665
B6: MEESHO | C6: MEESHO/AUG/0001 | D6: MEESHO/AUG/2132 | E6: 2132 | F6: 416 | G6: =E6-F6 -> 1716
B7: AJIO | G7: 0
B8: CREDIT NOTE
B10: name of the Company | C10: Invoice Series From | D10: Invoice Series To | E10: Total Number of Invoices | F10: Cancelled if any | G10: Net invoices Issued
B11: AMAZON | C11: CN-116 | D11: CN-138 | E11: =138-116+1 -> 23 | F11: 0 | G11: =E11 -> 23

Sheet conso hsn
A1: qty | B1: hsn | E1: taxable vlaue | F1: igst | G1: cgst | H1: sgst
A2: 1 | B2: 3926 | E2: 373.33333 | F2: 18.666667 | G2: 0 | H2: 0
A3: 4 | B3: 6109 | E3: 1536.2 | F3: 56.81 | G3: 10 | H3: 10
A4: 649 | B4: 6211 | E4: 183643.68 | F4: 7911.0842 | G4: 635.54981 | H4: 635.54981
A5: 2 | B5: 6302 | E5: 673.33333 | F5: 33.666667 | G5: 0 | H5: 0
A6: 2 | B6: 6304 | E6: 807.13333 | F6: 40.356667 | G6: 0 | H6: 0
A7: 1 | B7: 580610 | E7: -570.54286 | F7: -55.093333 | G7: 13.283095 | H7: 13.283095
A8: 233 | B8: 610510 | E8: 131500.61 | F8: 5490.8265 | G8: 542.102 | H8: 542.102
A9: 142 | B9: 611420 | E9: 39204.903 | F9: 1637.128 | G9: 161.55857 | H9: 161.55857
A10: 3 | B10: 620920 | E10: 1201.6952 | F10: 42.428571 | G10: 8.8280952 | H10: 8.8280952
A11: 825 | B11: 621132 | E11: 300993.73 | F11: 10732.3 | G11: 2158.6932 | H11: 2158.6932
A12: 6 | B12: 621133 | E12: 1570.8381 | F12: 64.684762 | G12: 6.9285714 | H12: 6.9285714
A13: 0 | B13: 621139 | E13: -77.142857 | F13: -27.619048 | G13: 11.880952 | H13: 11.880952
... A22: 2 | B22: 61119090 | E22: 752.38 | F22: 37.619 | G22: 0 | H22: 0
E23: =SUM(E2:E22) -> 825788.49 | F23: =SUM(F2:F22) -> 32623.031 | G23: =SUM(G2:G22) -> 4333.0575 | H23: =SUM(H2:H22) -> 4333.0575
